Workbook

Sheet 📊 Dashboard
B2: SALES PIPELINE DASHBOARD
B3: Real-Time Pipeline Overview • Track Leads, Deals & Revenue
B5: TOTAL PIPELINE | C5: WEIGHTED VALUE | D5: DEALS WON ($) | E5: WIN RATE | F5: AVG DEAL SIZE | G5: PIPELINE BY STAGE
B6: =Pipeline!T2 -> 251700 | C6: =Pipeline!T3 -> 133670 | D6: =Pipeline!T4 -> 25000 | E6: =Pipeline!T5 -> 0.5 | F6: =Pipeline!T6 -> 29070 | G6: Prospect | H6: =Pipeline!T8 -> 16700
G7: Qualified | H7: =Pipeline!T9 -> 40000
G8: Proposal | H8: =Pipeline!T10 -> 97000
G9: Negotiation | H9: =Pipeline!T11 -> 98000
B11: PIPELINE ACTIVITY SUMMARY
B12: Stage | C12: # Deals | D12: Total Value | E12: Weighted | F12: Avg Deal | G12: Best Deal | H12: Close This Mo.
B13: Prospect | C13: =COUNTIF(Pipeline!F:F,"Prospect") -> 2 | D13: =SUMIF(Pipeline!F:F,"Prospect",Pipeline!H:H) -> 16700 | E13: =SUMIF(Pipeline!F:F,"Prospect",Pipeline!K:K) -> 1670 | F13: =IFERROR(AVERAGEIF(Pipeline!F:F,"Prospect",Pipeline!H:H),0) -> 8350 | G13: =IFERROR(maxifs(Pipeline!H:H,Pipeline!F:F,"Prospect"),0) -> 0 | H13: =SUMIFS(Pipeline!H:H,Pipeline!F:F,"Prospect",Pipeline!G:G,">="&DATE(YEAR(TODAY()),MONTH(TODAY()),1),Pipeline!G:G,"<="&EOMONTH(TODAY(),0)) -> 0
B14: Qualified | C14: =COUNTIF(Pipeline!F:F,"Qualified") -> 2 | D14: =SUMIF(Pipeline!F:F,"Qualified",Pipeline!H:H) -> 40000 | E14: =SUMIF(Pipeline!F:F,"Qualified",Pipeline!K:K) -> 10000 | F14: =IFERROR(AVERAGEIF(Pipeline!F:F,"Qualified",Pipeline!H:H),0) -> 20000 | G14: =IFERROR(maxifs(Pipeline!H:H,Pipeline!F:F,"Qualified"),0) -> 0 | H14: =SUMIFS(Pipeline!H:H,Pipeline!F:F,"Qualified",Pipeline!G:G,">="&DATE(YEAR(TODAY()),MONTH(TODAY()),1),Pipeline!G:G,"<="&EOMONTH(TODAY(),0)) -> 0
B15: Proposal | C15: =COUNTIF(Pipeline!F:F,"Proposal") -> 2 | D15: =SUMIF(Pipeline!F:F,"Proposal",Pipeline!H:H) -> 97000 | E15: =SUMIF(Pipeline!F:F,"Proposal",Pipeline!K:K) -> 48500 | F15: =IFERROR(AVERAGEIF(Pipeline!F:F,"Proposal",Pipeline!H:H),0) -> 48500 | G15: =IFERROR(maxifs(Pipeline!H:H,Pipeline!F:F,"Proposal"),0) -> 0 | H15: =SUMIFS(Pipeline!H:H,Pipeline!F:F,"Proposal",Pipeline!G:G,">="&DATE(YEAR(TODAY()),MONTH(TODAY()),1),Pipeline!G:G,"<="&EOMONTH(TODAY(),0)) -> 0
B16: Negotiation | C16: =COUNTIF(Pipeline!F:F,"Negotiation") -> 2 | D16: =SUMIF(Pipeline!F:F,"Negotiation",Pipeline!H:H) -> 98000 | E16: =SUMIF(Pipeline!F:F,"Negotiation",Pipeline!K:K) -> 73500 | F16: =IFERROR(AVERAGEIF(Pipeline!F:F,"Negotiation",Pipeline!H:H),0) -> 49000 | G16: =IFERROR(maxifs(Pipeline!H:H,Pipeline!F:F,"Negotiation"),0) -> 0 | H16: =SUMIFS(Pipeline!H:H,Pipeline!F:F,"Negotiation",Pipeline!G:G,">="&DATE(YEAR(TODAY()),MONTH(TODAY()),1),Pipeline!G:G,"<="&EOMONTH(TODAY(),0)) -> 0
B17: Won | C17: =COUNTIF(Pipeline!F:F,"Won") -> 1 | D17: =SUMIF(Pipeline!F:F,"Won",Pipeline!H:H) -> 25000 | E17: =SUMIF(Pipeline!F:F,"Won",Pipeline!K:K) -> 25000 | F17: =IFERROR(AVERAGEIF(Pipeline!F:F,"Won",Pipeline!H:H),0) -> 25000 | G17: =IFERROR(maxifs(Pipeline!H:H,Pipeline!F:F,"Won"),0) -> 0 | H17: =SUMIFS(Pipeline!H:H,Pipeline!F:F,"Won",Pipeline!G:G,">="&DATE(YEAR(TODAY()),MONTH(TODAY()),1),Pipeline!G:G,"<="&EOMONTH(TODAY(),0)) -> 0
B18: Lost | C18: =COUNTIF(Pipeline!F:F,"Lost") -> 1 | D18: =SUMIF(Pipeline!F:F,"Lost",Pipeline!H:H) -> 14000 | E18: =SUMIF(Pipeline!F:F,"Lost",Pipeline!K:K) -> 0 | F18: =IFERROR(AVERAGEIF(Pipeline!F:F,"Lost",Pipeline!H:H),0) -> 14000 | G18: =IFERROR(maxifs(Pipeline!H:H,Pipeline!F:F,"Lost"),0) -> 0 | H18: =SUMIFS(Pipeline!H:H,Pipeline!F:F,"Lost",Pipeline!G:G,">="&DATE(YEAR(TODAY()),MONTH(TODAY()),1),Pipeline!G:G,"<="&EOMONTH(TODAY(),0)) -> 0
B20: 💡 Enter all deal data in the 📋 Pipeline tab • Use 📅 Monthly Tracker for trends • Review 🎯 Goal Tracker to hit your quota

Sheet Pipeline
A1: 📋 SALES PIPELINE TRACKER — Blue cells = your inputs | Black/Green cells = auto-calculated | Use dropdowns for Stage, Source & Priority | V1: =SUMPRODUCT((F3:F100<>"Won")*(F3:F100<>"Lost")*(F3:F100<>"")*H3:H100) -> 251700
A2: Deal ID | B2: Company | C2: Contact Name | D2: Contact Email | E2: Phone | F2: Stage | G2: Close Date | H2: Deal Value ($) | I2: Probability % | J2: Lead Source | K2: Weighted Value | L2: Days in Stage | M2: Owner | N2: Last Activity | O2: Next Action | P2: Priority | Q2: Notes | R2: Days to Close | T2: =SUMPRODUCT((F3:F100<>"Won")*(F3:F100<>"Lost")*(F3:F100<>"")*H3:H100) -> 251700
A3: =IF(B3<>"",(ROW()-2)&"","") -> 1 | B3: Acme Corp | C3: Jane Smith | D3: jane@acme.com | E3: 555-0101 | F3: Qualified | G3: 07/15/2025 | H3: 18000 | I3: =IFERROR(VLOOKUP(F3,S102:T107,2,FALSE()),0) -> 0.25 | J3: Inbound | K3: =H3*I3 -> 4500 | L3: =IFERROR(IF(N3<>"",TODAY()-N3,""),"") -> 364 | M3: John D | N3: 06/01/2025 | O3: Send proposal | P3: 🔴 High | Q3: Strong budget fit | R3: =IFERROR(IF(G3<>"",G3-TODAY(),""),"") -> -320 | T3: =SUMIFS(K3:K100,F3:F100,"<>Won",F3:F100,"<>Lost",B3:B100,"<>"&"") -> 133670 | V3: =SUMIF(F3:F100,"Won",H3:H100) -> 25000
A4: =IF(B4<>"",(ROW()-2)&"","") -> 2 | B4: Beta Solutions | C4: Mike Chen | D4: mike@beta.io | E4: 555-0102 | F4: Prospect | G4: 08/01/2025 | H4: 9500 | I4: =IFERROR(VLOOKUP(F4,S102:T107,2,FALSE()),0) -> 0.1 | J4: Cold Call | K4: =H4*I4 -> 950 | L4: =IFERROR(IF(N4<>"",TODAY()-N4,""),"") -> 368 | M4: Sarah K | N4: 05/28/2025 | O4: Discovery call | P4: 🟡 Medium | Q4: Early stage | R4: =IFERROR(IF(G4<>"",G4-TODAY(),""),"") -> -303 | T4: =SUMIF(F3:F100,"Won",H3:H100) -> 25000 | V4: =IFERROR(COUNTIF(F3:F100,"Won")/(COUNTIF(F3:F100,"Won")+COUNTIF(F3:F100,"Lost")),0) -> 0.5
A5: =IF(B5<>"",(ROW()-2)&"","") -> 3 | B5: Gamma LLC | C5: Lisa Ray | D5: lisa@gamma.com | E5: 555-0103 | F5: Proposal | G5: 06/30/2025 | H5: 42000 | I5: =IFERROR(VLOOKUP(F5,S102:T107,2,FALSE()),0) -> 0.5 | J5: Referral | K5: =H5*I5 -> 21000 | L5: =IFERROR(IF(N5<>"",TODAY()-N5,""),"") -> 366 | M5: John D | N5: 05/30/2025 | O5: Follow up on terms | P5: 🔴 High | Q5: Competitor eval | R5: =IFERROR(IF(G5<>"",G5-TODAY(),""),"") -> -335 | T5: =IFERROR(COUNTIF(F3:F100,"Won")/(COUNTIF(F3:F100,"Won")+COUNTIF(F3:F100,"Lost")),0) -> 0.5 | V5: =IFERROR(AVERAGEIF(H3:H100,">"&0,H3:H100),0) -> 29070
A6: =IF(B6<>"",(ROW()-2)&"","") -> 4 | B6: Delta Inc | C6: Tom West | D6: tom@delta.co | E6: 555-0104 | F6: Negotiation | G6: 06/20/2025 | H6: 31000 | I6: =IFERROR(VLOOKUP(F6,S102:T107,2,FALSE()),0) -> 0.75 | J6: Partner | K6: =H6*I6 -> 23250 | L6: =IFERROR(IF(N6<>"",TODAY()-N6,""),"") -> 367 | M6: Sarah K | N6: 05/29/2025 | O6: Contract review | P6: 🔴 High | Q6: Legal reviewing | R6: =IFERROR(IF(G6<>"",G6-TODAY(),""),"") -> -345 | T6: =IFERROR(AVERAGEIF(H3:H100,">"&0,H3:H100),0) -> 29070 | V6: =SUMIF(F3:F100,"Prospect",H3:H100) -> 16700
A7: =IF(B7<>"",(ROW()-2)&"","") -> 5 | B7: Epsilon Co | C7: Amy Liu | D7: amy@epsilon.com | E7: 555-0105 | F7: Won | G7: 05/15/2025 | H7: 25000 | I7: =IFERROR(VLOOKUP(F7,S102:T107,2,FALSE()),0) -> 1 | J7: Event | K7: =H7*I7 -> 25000 | L7: =IFERROR(IF(N7<>"",TODAY()-N7,""),"") -> 381 | M7: John D | N7: 05/15/2025 | O7: Kickoff meeting | P7: 🟢 Low | Q7: Closed! | R7: =IFERROR(IF(G7<>"",G7-TODAY(),""),"") -> -381 | V7: =SUMIF(F3:F100,"Qualified",H3:H100) -> 40000
A8: =IF(B8<>"",(ROW()-2)&"","") -> 6 | B8: Zeta Group | C8: Carl Brown | D8: carl@zeta.net | E8: 555-0106 | F8: Lost | G8: 04/30/2025 | H8: 14000 | I8: =IFERROR(VLOOKUP(F8,S102:T107,2,FALSE()),0) -> 0 | J8: Outbound | K8: =H8*I8 -> 0 | L8: =IFERROR(IF(N8<>"",TODAY()-N8,""),"") -> 396 | M8: Sarah K | N8: 04/30/2025 | O8: Post-mortem | P8: 🟢 Low | Q8: Chose competitor | R8: =IFERROR(IF(G8<>"",G8-TODAY(),""),"") -> -396 | T8: =SUMIF(F3:F100,"Prospect",H3:H100) -> 16700 | V8: =SUMIF(F3:F100,"Proposal",H3:H100) -> 97000
A9: =IF(B9<>"",(ROW()-2)&"","") -> 7 | B9: Eta Dynamics | C9: Nina Park | D9: nina@eta.com | E9: 555-0107 | F9: Qualified | G9: 07/20/2025 | H9: 22000 | I9: =IFERROR(VLOOKUP(F9,S102:T107,2,FALSE()),0) -> 0.25 | J9: Inbound | K9: =H9*I9 -> 5500 | L9: =IFERROR(IF(N9<>"",TODAY()-N9,""),"") -> 369 | M9: John D | N9: 05/27/2025 | O9: Demo scheduled | P9: 🟡 Medium | Q9: Good fit | R9: =IFERROR(IF(G9<>"",G9-TODAY(),""),"") -> -315 | T9: =SUMIF(F3:F100,"Qualified",H3:H100) -> 40000 | V9: =SUMIF(F3:F100,"Negotiation",H3:H100) -> 98000
A10: =IF(B10<>"",(ROW()-2)&"","") -> 8 | B10: Theta Works | C10: Dan Ford | D10: dan@theta.io | E10: 555-0108 | F10: Proposal | G10: 07/05/2025 | H10: 55000 | I10: =IFERROR(VLOOKUP(F10,S102:T107,2,FALSE()),0) -> 0.5 | J10: Referral | K10: =H10*I10 -> 27500 | L10: =IFERROR(IF(N10<>"",TODAY()-N10,""),"") -> 370 | M10: Sarah K | N10: 05/26/2025 | O10: Send updated scope | P10: 🔴 High | Q10: High value target | R10: =IFERROR(IF(G10<>"",G10-TODAY(),""),"") -> -330 | T10: =SUMIF(F3:F100,"Proposal",H3:H100) -> 97000
A11: =IF(B11<>"",(ROW()-2)&"","") -> 9 | B11: Iota Ltd | C11: Eva Moss | D11: eva@iota.co | E11: 555-0109 | F11: Prospect | G11: 08/15/2025 | H11: 7200 | I11: =IFERROR(VLOOKUP(F11,S102:T107,2,FALSE()),0) -> 0.1 | J11: Social | K11: =H11*I11 -> 720 | L11: =IFERROR(IF(N11<>"",TODAY()-N11,""),"") -> 371 | M11: John D | N11: 05/25/2025 | O11: LinkedIn connect | P11: 🟢 Low | Q11: Warm lead | R11: =IFERROR(IF(G11<>"",G11-TODAY(),""),"") -> -289 | T11: =SUMIF(F3:F100,"Negotiation",H3:H100) -> 98000
A12: =IF(B12<>"",(ROW()-2)&"","") -> 10 | B12: Kappa Ventures | C12: Rex King | D12: rex@kappa.com | E12: 555-0110 | F12: Negotiation | G12: 06/10/2025 | H12: 67000 | I12: =IFERROR(VLOOKUP(F12,S102:T107,2,FALSE()),0) -> 0.75 | J12: Inbound | K12: =H12*I12 -> 50250 | L12: =IFERROR(IF(N12<>"",TODAY()-N12,""),"") -> 368 | M12: Sarah K | N12: 05/28/2025 | O12: Final pricing call | P12: 🔴 High | Q12: Strategic account | R12: =IFERROR(IF(G12<>"",G12-TODAY(),""),"") -> -355
A13: =IF(B13<>"",(ROW()-2)&"","") | I13: =IFERROR(VLOOKUP(F13,S102:T107,2,FALSE()),0) -> 0 | K13: =IF(H13>0,H13*I13,"") | L13: =IFERROR(IF(N13<>"",TODAY()-N13,""),"") | R13: =IFERROR(IF(G13<>"",G13-TODAY(),""),"")
A14: =IF(B14<>"",(ROW()-2)&"","") | I14: =IFERROR(VLOOKUP(F14,S102:T107,2,FALSE()),0) -> 0 | K14: =IF(H14>0,H14*I14,"") | L14: =IFERROR(IF(N14<>"",TODAY()-N14,""),"") | R14: =IFERROR(IF(G14<>"",G14-TODAY(),""),"")
A15: =IF(B15<>"",(ROW()-2)&"","") | I15: =IFERROR(VLOOKUP(F15,S102:T107,2,FALSE()),0) -> 0 | K15: =IF(H15>0,H15*I15,"") | L15: =IFERROR(IF(N15<>"",TODAY()-N15,""),"") | R15: =IFERROR(IF(G15<>"",G15-TODAY(),""),"")
A16: =IF(B16<>"",(ROW()-2)&"","") | I16: =IFERROR(VLOOKUP(F16,S102:T107,2,FALSE()),0) -> 0 | K16: =IF(H16>0,H16*I16,"") | L16: =IFERROR(IF(N16<>"",TODAY()-N16,""),"") | R16: =IFERROR(IF(G16<>"",G16-TODAY(),""),"")
A17: =IF(B17<>"",(ROW()-2)&"","") | I17: =IFERROR(VLOOKUP(F17,S102:T107,2,FALSE()),0) -> 0 | K17: =IF(H17>0,H17*I17,"") | L17: =IFERROR(IF(N17<>"",TODAY()-N17,""),"") | R17: =IFERROR(IF(G17<>"",G17-TODAY(),""),"")
A18: =IF(B18<>"",(ROW()-2)&"","") | I18: =IFERROR(VLOOKUP(F18,S102:T107,2,FALSE()),0) -> 0 | K18: =IF(H18>0,H18*I18,"") | L18: =IFERROR(IF(N18<>"",TODAY()-N18,""),"") | R18: =IFERROR(IF(G18<>"",G18-TODAY(),""),"")
A19: =IF(B19<>"",(ROW()-2)&"","") | I19: =IFERROR(VLOOKUP(F19,S102:T107,2,FALSE()),0) -> 0 | K19: =IF(H19>0,H19*I19,"") | L19: =IFERROR(IF(N19<>"",TODAY()-N19,""),"") | R19: =IFERROR(IF(G19<>"",G19-TODAY(),""),"")
A20: =IF(B20<>"",(ROW()-2)&"","") | I20: =IFERROR(VLOOKUP(F20,S102:T107,2,FALSE()),0) -> 0 | K20: =IF(H20>0,H20*I20,"") | L20: =IFERROR(IF(N20<>"",TODAY()-N20,""),"") | R20: =IFERROR(IF(G20<>"",G20-TODAY(),""),"")
A21: =IF(B21<>"",(ROW()-2)&"","") | I21: =IFERROR(VLOOKUP(F21,S102:T107,2,FALSE()),0) -> 0 | K21: =IF(H21>0,H21*I21,"") | L21: =IFERROR(IF(N21<>"",TODAY()-N21,""),"") | R21: =IFERROR(IF(G21<>"",G21-TODAY(),""),"")
A22: =IF(B22<>"",(ROW()-2)&"","") | I22: =IFERROR(VLOOKUP(F22,S102:T107,2,FALSE()),0) -> 0 | K22: =IF(H22>0,H22*I22,"") | L22: =IFERROR(IF(N22<>"",TODAY()-N22,""),"") | R22: =IFERROR(IF(G22<>"",G22-TODAY(),""),"")
A23: =IF(B23<>"",(ROW()-2)&"","") | I23: =IFERROR(VLOOKUP(F23,S102:T107,2,FALSE()),0) -> 0 | K23: =IF(H23>0,H23*I23,"") | L23: =IFERROR(IF(N23<>"",TODAY()-N23,""),"") | R23: =IFERROR(IF(G23<>"",G23-TODAY(),""),"")
A24: =IF(B24<>"",(ROW()-2)&"","") | I24: =IFERROR(VLOOKUP(F24,S102:T107,2,FALSE()),0) -> 0 | K24: =IF(H24>0,H24*I24,"") | L24: =IFERROR(IF(N24<>"",TODAY()-N24,""),"") | R24: =IFERROR(IF(G24<>"",G24-TODAY(),""),"")
A25: =IF(B25<>"",(ROW()-2)&"","") | I25: =IFERROR(VLOOKUP(F25,S102:T107,2,FALSE()),0) -> 0 | K25: =IF(H25>0,H25*I25,"") | L25: =IFERROR(IF(N25<>"",TODAY()-N25,""),"") | R25: =IFERROR(IF(G25<>"",G25-TODAY(),""),"")
A26: =IF(B26<>"",(ROW()-2)&"","") | I26: =IFERROR(VLOOKUP(F26,S102:T107,2,FALSE()),0) -> 0 | K26: =IF(H26>0,H26*I26,"") | L26: =IFERROR(IF(N26<>"",TODAY()-N26,""),"") | R26: =IFERROR(IF(G26<>"",G26-TODAY(),""),"")
A27: =IF(B27<>"",(ROW()-2)&"","") | I27: =IFERROR(VLOOKUP(F27,S102:T107,2,FALSE()),0) -> 0 | K27: =IF(H27>0,H27*I27,"") | L27: =IFERROR(IF(N27<>"",TODAY()-N27,""),"") | R27: =IFERROR(IF(G27<>"",G27-TODAY(),""),"")
A28: =IF(B28<>"",(ROW()-2)&"","") | I28: =IFERROR(VLOOKUP(F28,S102:T107,2,FALSE()),0) -> 0 | K28: =IF(H28>0,H28*I28,"") | L28: =IFERROR(IF(N28<>"",TODAY()-N28,""),"") | R28: =IFERROR(IF(G28<>"",G28-TODAY(),""),"")
A29: =IF(B29<>"",(ROW()-2)&"","") | I29: =IFERROR(VLOOKUP(F29,S102:T107,2,FALSE()),0) -> 0 | K29: =IF(H29>0,H29*I29,"") | L29: =IFERROR(IF(N29<>"",TODAY()-N29,""),"") | R29: =IFERROR(IF(G29<>"",G29-TODAY(),""),"")
A30: =IF(B30<>"",(ROW()-2)&"","") | I30: =IFERROR(VLOOKUP(F30,S102:T107,2,FALSE()),0) -> 0 | K30: =IF(H30>0,H30*I30,"") | L30: =IFERROR(IF(N30<>"",TODAY()-N30,""),"") | R30: =IFERROR(IF(G30<>"",G30-TODAY(),""),"")
A31: =IF(B31<>"",(ROW()-2)&"","") | I31: =IFERROR(VLOOKUP(F31,S102:T107,2,FALSE()),0) -> 0 | K31: =IF(H31>0,H31*I31,"") | L31: =IFERROR(IF(N31<>"",TODAY()-N31,""),"") | R31: =IFERROR(IF(G31<>"",G31-TODAY(),""),"")
A32: =IF(B32<>"",(ROW()-2)&"","") | I32: =IFERROR(VLOOKUP(F32,S102:T107,2,FALSE()),0) -> 0 | K32: =IF(H32>0,H32*I32,"") | L32: =IFERROR(IF(N32<>"",TODAY()-N32,""),"") | R32: =IFERROR(IF(G32<>"",G32-TODAY(),""),"")
A33: =IF(B33<>"",(ROW()-2)&"","") | I33: =IFERROR(VLOOKUP(F33,S102:T107,2,FALSE()),0) -> 0 | K33: =IF(H33>0,H33*I33,"") | L33: =IFERROR(IF(N33<>"",TODAY()-N33,""),"") | R33: =IFERROR(IF(G33<>"",G33-TODAY(),""),"")
A34: =IF(B34<>"",(ROW()-2)&"","") | I34: =IFERROR(VLOOKUP(F34,S102:T107,2,FALSE()),0) -> 0 | K34: =IF(H34>0,H34*I34,"") | L34: =IFERROR(IF(N34<>"",TODAY()-N34,""),"") | R34: =IFERROR(IF(G34<>"",G34-TODAY(),""),"")
A35: =IF(B35<>"",(ROW()-2)&"","") | I35: =IFERROR(VLOOKUP(F35,S102:T107,2,FALSE()),0) -> 0 | K35: =IF(H35>0,H35*I35,"") | L35: =IFERROR(IF(N35<>"",TODAY()-N35,""),"") | R35: =IFERROR(IF(G35<>"",G35-TODAY(),""),"")
A36: =IF(B36<>"",(ROW()-2)&"","") | I36: =IFERROR(VLOOKUP(F36,S102:T107,2,FALSE()),0) -> 0 | K36: =IF(H36>0,H36*I36,"") | L36: =IFERROR(IF(N36<>"",TODAY()-N36,""),"") | R36: =IFERROR(IF(G36<>"",G36-TODAY(),""),"")
A37: =IF(B37<>"",(ROW()-2)&"","") | I37: =IFERROR(VLOOKUP(F37,S102:T107,2,FALSE()),0) -> 0 | K37: =IF(H37>0,H37*I37,"") | L37: =IFERROR(IF(N37<>"",TODAY()-N37,""),"") | R37: =IFERROR(IF(G37<>"",G37-TODAY(),""),"")
A38: =IF(B38<>"",(ROW()-2)&"","") | I38: =IFERROR(VLOOKUP(F38,S102:T107,2,FALSE()),0) -> 0 | K38: =IF(H38>0,H38*I38,"") | L38: =IFERROR(IF(N38<>"",TODAY()-N38,""),"") | R38: =IFERROR(IF(G38<>"",G38-TODAY(),""),"")
A39: =IF(B39<>"",(ROW()-2)&"","") | I39: =IFERROR(VLOOKUP(F39,S102:T107,2,FALSE()),0) -> 0 | K39: =IF(H39>0,H39*I39,"") | L39: =IFERROR(IF(N39<>"",TODAY()-N39,""),"") | R39: =IFERROR(IF(G39<>"",G39-TODAY(),""),"")
A40: =IF(B40<>"",(ROW()-2)&"","") | I40: =IFERROR(VLOOKUP(F40,S102:T107,2,FALSE()),0) -> 0 | K40: =IF(H40>0,H40*I40,"") | L40: =IFERROR(IF(N40<>"",TODAY()-N40,""),"") | R40: =IFERROR(IF(G40<>"",G40-TODAY(),""),"")
...

Sheet 📅 Monthly Tracker
A1: 📅 MONTHLY SALES TRACKER — Log activity each month to track trends and improve forecasting
A2: Month | B2: Year | C2: New Deals | D2: Deals Won | E2: Deals Lost | F2: New Pipeline ($) | G2: Won Revenue ($) | H2: Lost Revenue ($) | I2: Calls Made | J2: Emails Sent | K2: Demos Held | L2: Win Rate | M2: Conv. Rate | N2: Notes
A3: January | B3: 2025 | C3: 8 | D3: 3 | E3: 2 | F3: 145000 | G3: 62000 | H3: 18000 | I3: 42 | J3: 120 | K3: 8 | L3: =IFERROR(D3/(D3+E3),0) -> 0.6 | M3: =IFERROR(D3/C3,0) -> 0.375
A4: February | B4: 2025 | C4: 6 | D4: 2 | E4: 1 | F4: 112000 | G4: 43000 | H4: 9000 | I4: 38 | J4: 105 | K4: 6 | L4: =IFERROR(D4/(D4+E4),0) -> 0.66666667 | M4: =IFERROR(D4/C4,0) -> 0.33333333
A5: March | B5: 2025 | C5: 11 | D5: 5 | E5: 2 | F5: 198000 | G5: 97000 | H5: 22000 | I5: 55 | J5: 148 | K5: 12 | L5: =IFERROR(D5/(D5+E5),0) -> 0.71428571 | M5: =IFERROR(D5/C5,0) -> 0.45454545
A6: April | B6: 2025 | C6: 9 | D6: 4 | E6: 3 | F6: 167000 | G6: 81000 | H6: 31000 | I6: 49 | J6: 132 | K6: 10 | L6: =IFERROR(D6/(D6+E6),0) -> 0.57142857 | M6: =IFERROR(D6/C6,0) -> 0.44444444
A7: May | B7: 2025 | C7: 13 | D7: 6 | E7: 2 | F7: 241000 | G7: 118000 | H7: 19000 | I7: 61 | J7: 165 | K7: 15 | L7: =IFERROR(D7/(D7+E7),0) -> 0.75 | M7: =IFERROR(D7/C7,0) -> 0.46153846
L8: =IFERROR(D8/(D8+E8),0) -> 0 | M8: =IFERROR(D8/C8,0) -> 0
L9: =IFERROR(D9/(D9+E9),0) -> 0 | M9: =IFERROR(D9/C9,0) -> 0
L10: =IFERROR(D10/(D10+E10),0) -> 0 | M10: =IFERROR(D10/C10,0) -> 0
L11: =IFERROR(D11/(D11+E11),0) -> 0 | M11: =IFERROR(D11/C11,0) -> 0
L12: =IFERROR(D12/(D12+E12),0) -> 0 | M12: =IFERROR(D12/C12,0) -> 0
L13: =IFERROR(D13/(D13+E13),0) -> 0 | M13: =IFERROR(D13/C13,0) -> 0
L14: =IFERROR(D14/(D14+E14),0) -> 0 | M14: =IFERROR(D14/C14,0) -> 0
L15: =IFERROR(D15/(D15+E15),0) -> 0 | M15: =IFERROR(D15/C15,0) -> 0
L16: =IFERROR(D16/(D16+E16),0) -> 0 | M16: =IFERROR(D16/C16,0) -> 0
L17: =IFERROR(D17/(D17+E17),0) -> 0 | M17: =IFERROR(D17/C17,0) -> 0
L18: =IFERROR(D18/(D18+E18),0) -> 0 | M18: =IFERROR(D18/C18,0) -> 0
L19: =IFERROR(D19/(D19+E19),0) -> 0 | M19: =IFERROR(D19/C19,0) -> 0
... L24: =IFERROR(D24/(D24+E24),0) -> 0 | M24: =IFERROR(D24/C24,0) -> 0

Sheet 🎯 Goal Tracker
A1: 🎯 SALES GOAL TRACKER — Set annual and quarterly targets, track progress to quota
A2: Metric | B2: Annual Target | C2: Q1 Target | D2: Q2 Target | E2: Q3 Target | F2: Q4 Target | G2: YTD Actual | H2: % to Goal
A3: Revenue ($) | B3: 500000 | C3: 100000 | D3: 125000 | E3: 125000 | F3: 150000 | G3: =Pipeline!T4 -> 25000 | H3: =IFERROR(G3/B3,0) -> 0.05
A4: Deals Closed | B4: 40 | C4: 8 | D4: 10 | E4: 11 | F4: 11 | G4: =COUNTIF(Pipeline!F3:F100,"Won") -> 1 | H4: =IFERROR(G4/B4,0) -> 0.025
A5: Pipeline Created ($) | B5: 1500000 | C5: 350000 | D5: 375000 | E5: 375000 | F5: 400000 | G5: =Pipeline!T2 -> 251700 | H5: =IFERROR(G5/B5,0) -> 0.1678
A6: Calls Made | B6: 600 | C6: 140 | D6: 150 | E6: 155 | F6: 155 | G6: 0 | H6: =IFERROR(G6/B6,0) -> 0
A7: Demos Held | B7: 80 | C7: 18 | D7: 20 | E7: 21 | F7: 21 | G7: 0 | H7: =IFERROR(G7/B7,0) -> 0
A8: Avg Deal Size ($) | B8: 12500 | C8: 12000 | D8: 12500 | E8: 12500 | F8: 13000 | G8: =Pipeline!T6 -> 29070 | H8: =IFERROR(G8/B8,0) -> 2.3256
A9: Win Rate | B9: 0.35 | C9: 0.3 | D9: 0.33 | E9: 0.35 | F9: 0.38 | G9: =Pipeline!T5 -> 0.5 | H9: =IFERROR(G9/B9,0) -> 1.4285714

Sheet 📣 Source Analysis
A1: 📣 LEAD SOURCE ANALYSIS — Identify your highest-converting and highest-value channels
A2: Lead Source | B2: Total Deals | C2: Won Deals | D2: Lost Deals | E2: Total Value ($) | F2: Won Value ($) | G2: Win Rate
A3: Inbound | B3: =COUNTIF(Pipeline!J3:J100,A3) -> 3 | C3: =COUNTIFS(Pipeline!J3:J100,A3,Pipeline!F3:F100,"Won") -> 0 | D3: =COUNTIFS(Pipeline!J3:J100,A3,Pipeline!F3:F100,"Lost") -> 0 | E3: =SUMIF(Pipeline!J3:J100,A3,Pipeline!H3:H100) -> 107000 | F3: =SUMIFS(Pipeline!H3:H100,Pipeline!J3:J100,A3,Pipeline!F3:F100,"Won") -> 0 | G3: =IFERROR(C3/(C3+D3),0) -> 0
A4: Outbound | B4: =COUNTIF(Pipeline!J3:J100,A4) -> 1 | C4: =COUNTIFS(Pipeline!J3:J100,A4,Pipeline!F3:F100,"Won") -> 0 | D4: =COUNTIFS(Pipeline!J3:J100,A4,Pipeline!F3:F100,"Lost") -> 1 | E4: =SUMIF(Pipeline!J3:J100,A4,Pipeline!H3:H100) -> 14000 | F4: =SUMIFS(Pipeline!H3:H100,Pipeline!J3:J100,A4,Pipeline!F3:F100,"Won") -> 0 | G4: =IFERROR(C4/(C4+D4),0) -> 0
A5: Referral | B5: =COUNTIF(Pipeline!J3:J100,A5) -> 2 | C5: =COUNTIFS(Pipeline!J3:J100,A5,Pipeline!F3:F100,"Won") -> 0 | D5: =COUNTIFS(Pipeline!J3:J100,A5,Pipeline!F3:F100,"Lost") -> 0 | E5: =SUMIF(Pipeline!J3:J100,A5,Pipeline!H3:H100) -> 97000 | F5: =SUMIFS(Pipeline!H3:H100,Pipeline!J3:J100,A5,Pipeline!F3:F100,"Won") -> 0 | G5: =IFERROR(C5/(C5+D5),0) -> 0
A6: Partner | B6: =COUNTIF(Pipeline!J3:J100,A6) -> 1 | C6: =COUNTIFS(Pipeline!J3:J100,A6,Pipeline!F3:F100,"Won") -> 0 | D6: =COUNTIFS(Pipeline!J3:J100,A6,Pipeline!F3:F100,"Lost") -> 0 | E6: =SUMIF(Pipeline!J3:J100,A6,Pipeline!H3:H100) -> 31000 | F6: =SUMIFS(Pipeline!H3:H100,Pipeline!J3:J100,A6,Pipeline!F3:F100,"Won") -> 0 | G6: =IFERROR(C6/(C6+D6),0) -> 0
A7: Event | B7: =COUNTIF(Pipeline!J3:J100,A7) -> 1 | C7: =COUNTIFS(Pipeline!J3:J100,A7,Pipeline!F3:F100,"Won") -> 1 | D7: =COUNTIFS(Pipeline!J3:J100,A7,Pipeline!F3:F100,"Lost") -> 0 | E7: =SUMIF(Pipeline!J3:J100,A7,Pipeline!H3:H100) -> 25000 | F7: =SUMIFS(Pipeline!H3:H100,Pipeline!J3:J100,A7,Pipeline!F3:F100,"Won") -> 25000 | G7: =IFERROR(C7/(C7+D7),0) -> 1
A8: Social | B8: =COUNTIF(Pipeline!J3:J100,A8) -> 1 | C8: =COUNTIFS(Pipeline!J3:J100,A8,Pipeline!F3:F100,"Won") -> 0 | D8: =COUNTIFS(Pipeline!J3:J100,A8,Pipeline!F3:F100,"Lost") -> 0 | E8: =SUMIF(Pipeline!J3:J100,A8,Pipeline!H3:H100) -> 7200 | F8: =SUMIFS(Pipeline!H3:H100,Pipeline!J3:J100,A8,Pipeline!F3:F100,"Won") -> 0 | G8: =IFERROR(C8/(C8+D8),0) -> 0
A9: Email | B9: =COUNTIF(Pipeline!J3:J100,A9) -> 0 | C9: =COUNTIFS(Pipeline!J3:J100,A9,Pipeline!F3:F100,"Won") -> 0 | D9: =COUNTIFS(Pipeline!J3:J100,A9,Pipeline!F3:F100,"Lost") -> 0 | E9: =SUMIF(Pipeline!J3:J100,A9,Pipeline!H3:H100) -> 0 | F9: =SUMIFS(Pipeline!H3:H100,Pipeline!J3:J100,A9,Pipeline!F3:F100,"Won") -> 0 | G9: =IFERROR(C9/(C9+D9),0) -> 0
A10: Cold Call | B10: =COUNTIF(Pipeline!J3:J100,A10) -> 1 | C10: =COUNTIFS(Pipeline!J3:J100,A10,Pipeline!F3:F100,"Won") -> 0 | D10: =COUNTIFS(Pipeline!J3:J100,A10,Pipeline!F3:F100,"Lost") -> 0 | E10: =SUMIF(Pipeline!J3:J100,A10,Pipeline!H3:H100) -> 9500 | F10: =SUMIFS(Pipeline!H3:H100,Pipeline!J3:J100,A10,Pipeline!F3:F100,"Won") -> 0 | G10: =IFERROR(C10/(C10+D10),0) -> 0
A11: Other | B11: =COUNTIF(Pipeline!J3:J100,A11) -> 0 | C11: =COUNTIFS(Pipeline!J3:J100,A11,Pipeline!F3:F100,"Won") -> 0 | D11: =COUNTIFS(Pipeline!J3:J100,A11,Pipeline!F3:F100,"Lost") -> 0 | E11: =SUMIF(Pipeline!J3:J100,A11,Pipeline!H3:H100) -> 0 | F11: =SUMIFS(Pipeline!H3:H100,Pipeline!J3:J100,A11,Pipeline!F3:F100,"Won") -> 0 | G11: =IFERROR(C11/(C11+D11),0) -> 0

Sheet 📖 How To Use
B1: 📖 QUICK START GUIDE — Sales Pipeline Tracker Pro
B3: QUICK START
B4: Step 1 — Open Pipeline tab | C4: Go to 📋 Pipeline. This is your main data entry sheet. All other sheets update automatically.
B5: Step 2 — Fill blue cells | C5: Enter Company, Contact, Email, Phone, Stage (dropdown), Close Date, Deal Value ($), Lead Source (dropdown), Owner, Last Activity date, Next Action, Priority (dropdown), and Notes.
B6: Step 3 — Auto-calculations | C6: Deal ID, Probability %, Weighted Value, Days in Stage, and Days to Close all calculate automatically. Do not edit these columns.
B7: Step 4 — Check Dashboard | C7: 📊 Dashboard updates in real time. Review it in your weekly pipeline meeting for instant visibility.
B8: Step 5 — Log monthly data | C8: Each month, record activity in 📅 Monthly Tracker to build trend history over time.
B9: Step 6 — Set your goals | C9: Update 🎯 Goal Tracker at start of each quarter with your revenue and activity targets.
B11: PIPELINE STAGES
B12: Prospect — 10% probability | C12: Initial contact. You believe there's a potential fit. Not yet qualified.
B13: Qualified — 25% probability | C13: BANT confirmed: Budget, Authority, Need, Timeline. Real opportunity.
B14: Proposal — 50% probability | C14: You've submitted or scheduled a formal proposal or demo.
B15: Negotiation — 75% probability | C15: In active pricing or contract discussions. Near the finish line.
B16: Won — 100% | C16: Deal signed. Row turns green automatically. Counted in revenue metrics.
B17: Lost — 0% | C17: Opportunity lost. Row turns gray. Counted in loss rate metrics.
B19: COLOR GUIDE
B20: Blue text cells | C20: YOUR inputs — fill these in for each deal.
B21: Green text cells | C21: Formulas pulling from other sheets — do not edit.
B22: Black text cells | C22: Calculated formulas on the same sheet — do not edit.
B23: Green row background | C23: Won deal — closed successfully.
B24: Gray row background | C24: Lost deal — closed unsuccessfully.
B25: Yellow row background | C25: High priority deal requiring immediate attention.
B27: BEST PRACTICES
B28: Update daily (5 minutes) | C28: Each morning: update Last Activity and Next Action for your top 5 deals. Stale data = bad forecasts.
B29: Watch Days in Stage | C29: Any deal stuck >30 days in Prospect or Qualified needs a decision: advance or mark Lost.
B30: Use the Notes column | C30: Add competitor mentions, budget signals, champion names, and objections. This is your CRM.
B31: Review weekly | C31: Use 📊 Dashboard in your Monday pipeline review. Focus on Weighted Value, not just Total Pipeline.
B32: Track activity monthly | C32: Log calls, emails, demos in 📅 Monthly Tracker. Win rate trends reveal coaching opportunities.
B33: Update goals quarterly | C33: Set realistic targets in 🎯 Goal Tracker. Review % to Goal weekly — don't wait until month-end.
